<mujoco model="BrittleStarMorphology">
  <compiler angle="radian"/>
  <default>
    <default class="/">
      <geom contype="1" conaffinity="0" condim="4"/>
    </default>
  </default>
  <worldbody>
    <body name="central_disk" pos="0 0 0" euler="0 0 0">
      <geom name="central_disk_pentagon_side_0" class="/" type="box" contype="0" conaffinity="0" size="0.050563562148434216 0.073473156536559142 0.025000000000000001" rgba="0.49019607843137253 0.70980392156862748 0.6588235294117647 1" pos="0.040906781074217108 0.029720516134223551 0" euler="0 0 0.62831853071795862"/>
      <geom name="central_disk_pentagon_side_1" class="/" type="box" contype="0" conaffinity="0" size="0.050563562148434216 0.073473156536559142 0.025000000000000001" rgba="0.49019607843137253 0.70980392156862748 0.6588235294117647 1" pos="-0.015624999999999997 0.048088805268363337 0" euler="0 0 1.8849555921538759"/>
      <geom name="central_disk_pentagon_side_2" class="/" type="box" contype="0" conaffinity="0" size="0.050563562148434216 0.073473156536559142 0.025000000000000001" rgba="0.49019607843137253 0.70980392156862748 0.6588235294117647 1" pos="-0.050563562148434216 6.1922504538568225e-18 0" euler="0 0 3.1415926535897931"/>
      <geom name="central_disk_pentagon_side_3" class="/" type="box" contype="0" conaffinity="0" size="0.050563562148434216 0.073473156536559142 0.025000000000000001" rgba="0.49019607843137253 0.70980392156862748 0.6588235294117647 1" pos="-0.015625000000000007 -0.048088805268363337 0" euler="0 0 4.3982297150257104"/>
      <geom name="central_disk_pentagon_side_4" class="/" type="box" contype="0" conaffinity="0" size="0.050563562148434216 0.073473156536559142 0.025000000000000001" rgba="0.49019607843137253 0.70980392156862748 0.6588235294117647 1" pos="0.040906781074217101 -0.029720516134223562 0" euler="0 0 5.6548667764616276"/>
      <geom name="central_disk_pentagon_collider" class="/" type="box" contype="1" conaffinity="0" size="0.068750000000000006 0.068750000000000006 0.025000000000000001" rgba="0.49019607843137253 0.70980392156862748 0.6588235294117647 1" pos="0 0 0" euler="0 0 0"/>
      <geom name="central_disk_arm_connector_0" class="/" type="box" contype="0" conaffinity="0" size="0.025000000000000001 0.027500000000000004 0.025000000000000001" rgba="0.49019607843137253 0.70980392156862748 0.6588235294117647 1" pos="0.10000000000000001 0 0" euler="0 0 0"/>
      <geom name="central_disk_arm_connector_1" class="/" type="box" contype="0" conaffinity="0" size="0.025000000000000001 0.027500000000000004 0.025000000000000001" rgba="0.49019607843137253 0.70980392156862748 0.6588235294117647 1" pos="0.030901699437494747 0.095105651629515356 0" euler="0 0 1.2566370614359172"/>
      <geom name="central_disk_arm_connector_2" class="/" type="box" contype="0" conaffinity="0" size="0.025000000000000001 0.027500000000000004 0.025000000000000001" rgba="0.49019607843137253 0.70980392156862748 0.6588235294117647 1" pos="-0.080901699437494742 0.058778525229247328 0" euler="0 0 2.5132741228718345"/>
      <geom name="central_disk_arm_connector_3" class="/" type="box" contype="0" conaffinity="0" size="0.025000000000000001 0.027500000000000004 0.025000000000000001" rgba="0.49019607843137253 0.70980392156862748 0.6588235294117647 1" pos="-0.080901699437494756 -0.058778525229247307 0" euler="0 0 3.7699111843077517"/>
      <geom name="central_disk_arm_connector_4" class="/" type="box" contype="0" conaffinity="0" size="0.025000000000000001 0.027500000000000004 0.025000000000000001" rgba="0.49019607843137253 0.70980392156862748 0.6588235294117647 1" pos="0.030901699437494726 -0.09510565162951537 0" euler="0 0 5.026548245743669"/>
      <body name="arm_0" pos="0.125 0 0" euler="0 0 0">
        <body name="arm_0_segment_0" pos="0 0 0" euler="0 0 0">
          <geom name="arm_0_segment_0_capsule" class="/" type="capsule" size="0.025000000000000001 0.037499999999999999" rgba="0.49019607843137253 0.70980392156862748 0.6588235294117647 1" pos="0.0625 0 0" euler="0 1.5707963267948966 0"/>
          <geom name="arm_0_segment_0_connector" class="/" type="sphere" contype="0" conaffinity="0" size="0.012500000000000001" rgba="0.34901960784313724 0.34901960784313724 0.34901960784313724 1" pos="0 0 0"/>
          <joint name="arm_0_segment_0_in_plane_joint" class="/" type="hinge" axis="0 0 1" limited="true" stiffness="0.01" range="-0.52359877559829882 0.52359877559829882" armature="0.01" damping="0.10000000000000001"/>
          <joint name="arm_0_segment_0_out_of_plane_joint" class="/" type="hinge" axis="0 -1 0" limited="true" stiffness="0.01" range="-0.52359877559829882 0.52359877559829882" armature="0.01" damping="0.10000000000000001"/>
          <body name="arm_0_segment_1" pos="0.125 0 0" euler="0 0 0">
            <geom name="arm_0_segment_1_capsule" class="/" type="capsule" size="0.022499999999999999 0.032500000000000001" rgba="0.49019607843137253 0.70980392156862748 0.6588235294117647 1" pos="0.055 0 0" euler="0 1.5707963267948966 0"/>
            <geom name="arm_0_segment_1_connector" class="/" type="sphere" contype="0" conaffinity="0" size="0.01125" rgba="0.34901960784313724 0.34901960784313724 0.34901960784313724 1" pos="0 0 0"/>
            <joint name="arm_0_segment_1_in_plane_joint" class="/" type="hinge" axis="0 0 1" limited="true" stiffness="0.01" range="-0.52359877559829882 0.52359877559829882" armature="0.01" damping="0.10000000000000001"/>
            <joint name="arm_0_segment_1_out_of_plane_joint" class="/" type="hinge" axis="0 -1 0" limited="true" stiffness="0.01" range="-0.52359877559829882 0.52359877559829882" armature="0.01" damping="0.10000000000000001"/>
            <body name="arm_0_segment_2" pos="0.11 0 0" euler="0 0 0">
              <geom name="arm_0_segment_2_capsule" class="/" type="capsule" size="0.02 0.027499999999999997" rgba="0.49019607843137253 0.70980392156862748 0.6588235294117647 1" pos="0.047500000000000001 0 0" euler="0 1.5707963267948966 0"/>
              <geom name="arm_0_segment_2_connector" class="/" type="sphere" contype="0" conaffinity="0" size="0.01" rgba="0.34901960784313724 0.34901960784313724 0.34901960784313724 1" pos="0 0 0"/>
              <joint name="arm_0_segment_2_in_plane_joint" class="/" type="hinge" axis="0 0 1" limited="true" stiffness="0.01" range="-0.52359877559829882 0.52359877559829882" armature="0.01" damping="0.10000000000000001"/>
              <joint name="arm_0_segment_2_out_of_plane_joint" class="/" type="hinge" axis="0 -1 0" limited="true" stiffness="0.01" range="-0.52359877559829882 0.52359877559829882" armature="0.01" damping="0.10000000000000001"/>
              <body name="arm_0_segment_3" pos="0.095000000000000001 0 0" euler="0 0 0">
                <geom name="arm_0_segment_3_capsule" class="/" type="capsule" size="0.017500000000000002 0.022499999999999999" rgba="0.49019607843137253 0.70980392156862748 0.6588235294117647 1" pos="0.040000000000000001 0 0" euler="0 1.5707963267948966 0"/>
                <geom name="arm_0_segment_3_connector" class="/" type="sphere" contype="0" conaffinity="0" size="0.0087500000000000008" rgba="0.34901960784313724 0.34901960784313724 0.34901960784313724 1" pos="0 0 0"/>
                <joint name="arm_0_segment_3_in_plane_joint" class="/" type="hinge" axis="0 0 1" limited="true" stiffness="0.01" range="-0.52359877559829882 0.52359877559829882" armature="0.01" damping="0.10000000000000001"/>
                <joint name="arm_0_segment_3_out_of_plane_joint" class="/" type="hinge" axis="0 -1 0" limited="true" stiffness="0.01" range="-0.52359877559829882 0.52359877559829882" armature="0.01" damping="0.10000000000000001"/>
                <body name="arm_0_segment_4" pos="0.080000000000000002 0 0" euler="0 0 0">
                  <geom name="arm_0_segment_4_capsule" class="/" type="capsule" size="0.014999999999999999 0.017499999999999998" rgba="0.49019607843137253 0.70980392156862748 0.6588235294117647 1" pos="0.032500000000000001 0 0" euler="0 1.5707963267948966 0"/>
                  <geom name="arm_0_segment_4_connector" class="/" type="sphere" contype="0" conaffinity="0" size="0.0074999999999999997" rgba="0.34901960784313724 0.34901960784313724 0.34901960784313724 1" pos="0 0 0"/>
                  <joint name="arm_0_segment_4_in_plane_joint" class="/" type="hinge" axis="0 0 1" limited="true" stiffness="0.01" range="-0.52359877559829882 0.52359877559829882" armature="0.01" damping="0.10000000000000001"/>
                  <joint name="arm_0_segment_4_out_of_plane_joint" class="/" type="hinge" axis="0 -1 0" limited="true" stiffness="0.01" range="-0.52359877559829882 0.52359877559829882" armature="0.01" damping="0.10000000000000001"/>
                </body>
              </body>
            </body>
          </body>
        </body>
      </body>
      <body name="arm_1" pos="0.038627124296868431 0.11888206453689419 0" euler="0 0 1.2566370614359172">
        <body name="arm_1_segment_0" pos="0 0 0" euler="0 0 0">
          <geom name="arm_1_segment_0_capsule" class="/" type="capsule" size="0.025000000000000001 0.037499999999999999" rgba="0.49019607843137253 0.70980392156862748 0.6588235294117647 1" pos="0.0625 0 0" euler="0 1.5707963267948966 0"/>
          <geom name="arm_1_segment_0_connector" class="/" type="sphere" contype="0" conaffinity="0" size="0.012500000000000001" rgba="0.34901960784313724 0.34901960784313724 0.34901960784313724 1" pos="0 0 0"/>
          <joint name="arm_1_segment_0_in_plane_joint" class="/" type="hinge" axis="0 0 1" limited="true" stiffness="0.01" range="-0.52359877559829882 0.52359877559829882" armature="0.01" damping="0.10000000000000001"/>
          <joint name="arm_1_segment_0_out_of_plane_joint" class="/" type="hinge" axis="0 -1 0" limited="true" stiffness="0.01" range="-0.52359877559829882 0.52359877559829882" armature="0.01" damping="0.10000000000000001"/>
          <body name="arm_1_segment_1" pos="0.125 0 0" euler="0 0 0">
            <geom name="arm_1_segment_1_capsule" class="/" type="capsule" size="0.022499999999999999 0.032500000000000001" rgba="0.49019607843137253 0.70980392156862748 0.6588235294117647 1" pos="0.055 0 0" euler="0 1.5707963267948966 0"/>
            <geom name="arm_1_segment_1_connector" class="/" type="sphere" contype="0" conaffinity="0" size="0.01125" rgba="0.34901960784313724 0.34901960784313724 0.34901960784313724 1" pos="0 0 0"/>
            <joint name="arm_1_segment_1_in_plane_joint" class="/" type="hinge" axis="0 0 1" limited="true" stiffness="0.01" range="-0.52359877559829882 0.52359877559829882" armature="0.01" damping="0.10000000000000001"/>
            <joint name="arm_1_segment_1_out_of_plane_joint" class="/" type="hinge" axis="0 -1 0" limited="true" stiffness="0.01" range="-0.52359877559829882 0.52359877559829882" armature="0.01" damping="0.10000000000000001"/>
            <body name="arm_1_segment_2" pos="0.11 0 0" euler="0 0 0">
              <geom name="arm_1_segment_2_capsule" class="/" type="capsule" size="0.02 0.027499999999999997" rgba="0.49019607843137253 0.70980392156862748 0.6588235294117647 1" pos="0.047500000000000001 0 0" euler="0 1.5707963267948966 0"/>
              <geom name="arm_1_segment_2_connector" class="/" type="sphere" contype="0" conaffinity="0" size="0.01" rgba="0.34901960784313724 0.34901960784313724 0.34901960784313724 1" pos="0 0 0"/>
              <joint name="arm_1_segment_2_in_plane_joint" class="/" type="hinge" axis="0 0 1" limited="true" stiffness="0.01" range="-0.52359877559829882 0.52359877559829882" armature="0.01" damping="0.10000000000000001"/>
              <joint name="arm_1_segment_2_out_of_plane_joint" class="/" type="hinge" axis="0 -1 0" limited="true" stiffness="0.01" range="-0.52359877559829882 0.52359877559829882" armature="0.01" damping="0.10000000000000001"/>
              <body name="arm_1_segment_3" pos="0.095000000000000001 0 0" euler="0 0 0">
                <geom name="arm_1_segment_3_capsule" class="/" type="capsule" size="0.017500000000000002 0.022499999999999999" rgba="0.49019607843137253 0.70980392156862748 0.6588235294117647 1" pos="0.040000000000000001 0 0" euler="0 1.5707963267948966 0"/>
                <geom name="arm_1_segment_3_connector" class="/" type="sphere" contype="0" conaffinity="0" size="0.0087500000000000008" rgba="0.34901960784313724 0.34901960784313724 0.34901960784313724 1" pos="0 0 0"/>
                <joint name="arm_1_segment_3_in_plane_joint" class="/" type="hinge" axis="0 0 1" limited="true" stiffness="0.01" range="-0.52359877559829882 0.52359877559829882" armature="0.01" damping="0.10000000000000001"/>
                <joint name="arm_1_segment_3_out_of_plane_joint" class="/" type="hinge" axis="0 -1 0" limited="true" stiffness="0.01" range="-0.52359877559829882 0.52359877559829882" armature="0.01" damping="0.10000000000000001"/>
                <body name="arm_1_segment_4" pos="0.080000000000000002 0 0" euler="0 0 0">
                  <geom name="arm_1_segment_4_capsule" class="/" type="capsule" size="0.014999999999999999 0.017499999999999998" rgba="0.49019607843137253 0.70980392156862748 0.6588235294117647 1" pos="0.032500000000000001 0 0" euler="0 1.5707963267948966 0"/>
                  <geom name="arm_1_segment_4_connector" class="/" type="sphere" contype="0" conaffinity="0" size="0.0074999999999999997" rgba="0.34901960784313724 0.34901960784313724 0.34901960784313724 1" pos="0 0 0"/>
                  <joint name="arm_1_segment_4_in_plane_joint" class="/" type="hinge" axis="0 0 1" limited="true" stiffness="0.01" range="-0.52359877559829882 0.52359877559829882" armature="0.01" damping="0.10000000000000001"/>
                  <joint name="arm_1_segment_4_out_of_plane_joint" class="/" type="hinge" axis="0 -1 0" limited="true" stiffness="0.01" range="-0.52359877559829882 0.52359877559829882" armature="0.01" damping="0.10000000000000001"/>
                </body>
              </body>
            </body>
          </body>
        </body>
      </body>
      <body name="arm_2" pos="-0.10112712429686842 0.073473156536559156 0" euler="0 0 2.5132741228718345">
        <body name="arm_2_segment_0" pos="0 0 0" euler="0 0 0">
          <geom name="arm_2_segment_0_capsule" class="/" type="capsule" size="0.025000000000000001 0.037499999999999999" rgba="0.49019607843137253 0.70980392156862748 0.6588235294117647 1" pos="0.0625 0 0" euler="0 1.5707963267948966 0"/>
          <geom name="arm_2_segment_0_connector" class="/" type="sphere" contype="0" conaffinity="0" size="0.012500000000000001" rgba="0.34901960784313724 0.34901960784313724 0.34901960784313724 1" pos="0 0 0"/>
          <joint name="arm_2_segment_0_in_plane_joint" class="/" type="hinge" axis="0 0 1" limited="true" stiffness="0.01" range="-0.52359877559829882 0.52359877559829882" armature="0.01" damping="0.10000000000000001"/>
          <joint name="arm_2_segment_0_out_of_plane_joint" class="/" type="hinge" axis="0 -1 0" limited="true" stiffness="0.01" range="-0.52359877559829882 0.52359877559829882" armature="0.01" damping="0.10000000000000001"/>
          <body name="arm_2_segment_1" pos="0.125 0 0" euler="0 0 0">
            <geom name="arm_2_segment_1_capsule" class="/" type="capsule" size="0.022499999999999999 0.032500000000000001" rgba="0.49019607843137253 0.70980392156862748 0.6588235294117647 1" pos="0.055 0 0" euler="0 1.5707963267948966 0"/>
            <geom name="arm_2_segment_1_connector" class="/" type="sphere" contype="0" conaffinity="0" size="0.01125" rgba="0.34901960784313724 0.34901960784313724 0.34901960784313724 1" pos="0 0 0"/>
            <joint name="arm_2_segment_1_in_plane_joint" class="/" type="hinge" axis="0 0 1" limited="true" stiffness="0.01" range="-0.52359877559829882 0.52359877559829882" armature="0.01" damping="0.10000000000000001"/>
            <joint name="arm_2_segment_1_out_of_plane_joint" class="/" type="hinge" axis="0 -1 0" limited="true" stiffness="0.01" range="-0.52359877559829882 0.52359877559829882" armature="0.01" damping="0.10000000000000001"/>
            <body name="arm_2_segment_2" pos="0.11 0 0" euler="0 0 0">
              <geom name="arm_2_segment_2_capsule" class="/" type="capsule" size="0.02 0.027499999999999997" rgba="0.49019607843137253 0.70980392156862748 0.6588235294117647 1" pos="0.047500000000000001 0 0" euler="0 1.5707963267948966 0"/>
              <geom name="arm_2_segment_2_connector" class="/" type="sphere" contype="0" conaffinity="0" size="0.01" rgba="0.34901960784313724 0.34901960784313724 0.34901960784313724 1" pos="0 0 0"/>
              <joint name="arm_2_segment_2_in_plane_joint" class="/" type="hinge" axis="0 0 1" limited="true" stiffness="0.01" range="-0.52359877559829882 0.52359877559829882" armature="0.01" damping="0.10000000000000001"/>
              <joint name="arm_2_segment_2_out_of_plane_joint" class="/" type="hinge" axis="0 -1 0" limited="true" stiffness="0.01" range="-0.52359877559829882 0.52359877559829882" armature="0.01" damping="0.10000000000000001"/>
              <body name="arm_2_segment_3" pos="0.095000000000000001 0 0" euler="0 0 0">
                <geom name="arm_2_segment_3_capsule" class="/" type="capsule" size="0.017500000000000002 0.022499999999999999" rgba="0.49019607843137253 0.70980392156862748 0.6588235294117647 1" pos="0.040000000000000001 0 0" euler="0 1.5707963267948966 0"/>
                <geom name="arm_2_segment_3_connector" class="/" type="sphere" contype="0" conaffinity="0" size="0.0087500000000000008" rgba="0.34901960784313724 0.34901960784313724 0.34901960784313724 1" pos="0 0 0"/>
                <joint name="arm_2_segment_3_in_plane_joint" class="/" type="hinge" axis="0 0 1" limited="true" stiffness="0.01" range="-0.52359877559829882 0.52359877559829882" armature="0.01" damping="0.10000000000000001"/>
                <joint name="arm_2_segment_3_out_of_plane_joint" class="/" type="hinge" axis="0 -1 0" limited="true" stiffness="0.01" range="-0.52359877559829882 0.52359877559829882" armature="0.01" damping="0.10000000000000001"/>
                <body name="arm_2_segment_4" pos="0.080000000000000002 0 0" euler="0 0 0">
                  <geom name="arm_2_segment_4_capsule" class="/" type="capsule" size="0.014999999999999999 0.017499999999999998" rgba="0.49019607843137253 0.70980392156862748 0.6588235294117647 1" pos="0.032500000000000001 0 0" euler="0 1.5707963267948966 0"/>
                  <geom name="arm_2_segment_4_connector" class="/" type="sphere" contype="0" conaffinity="0" size="0.0074999999999999997" rgba="0.34901960784313724 0.34901960784313724 0.34901960784313724 1" pos="0 0 0"/>
                  <joint name="arm_2_segment_4_in_plane_joint" class="/" type="hinge" axis="0 0 1" limited="true" stiffness="0.01" range="-0.52359877559829882 0.52359877559829882" armature="0.01" damping="0.10000000000000001"/>
                  <joint name="arm_2_segment_4_out_of_plane_joint" class="/" type="hinge" axis="0 -1 0" limited="true" stiffness="0.01" range="-0.52359877559829882 0.52359877559829882" armature="0.01" damping="0.10000000000000001"/>
                </body>
              </body>
            </body>
          </body>
        </body>
      </body>
      <body name="arm_3" pos="-0.10112712429686843 -0.073473156536559128 0" euler="0 0 3.7699111843077517">
        <body name="arm_3_segment_0" pos="0 0 0" euler="0 0 0">
          <geom name="arm_3_segment_0_capsule" class="/" type="capsule" size="0.025000000000000001 0.037499999999999999" rgba="0.49019607843137253 0.70980392156862748 0.6588235294117647 1" pos="0.0625 0 0" euler="0 1.5707963267948966 0"/>
          <geom name="arm_3_segment_0_connector" class="/" type="sphere" contype="0" conaffinity="0" size="0.012500000000000001" rgba="0.34901960784313724 0.34901960784313724 0.34901960784313724 1" pos="0 0 0"/>
          <joint name="arm_3_segment_0_in_plane_joint" class="/" type="hinge" axis="0 0 1" limited="true" stiffness="0.01" range="-0.52359877559829882 0.52359877559829882" armature="0.01" damping="0.10000000000000001"/>
          <joint name="arm_3_segment_0_out_of_plane_joint" class="/" type="hinge" axis="0 -1 0" limited="true" stiffness="0.01" range="-0.52359877559829882 0.52359877559829882" armature="0.01" damping="0.10000000000000001"/>
          <body name="arm_3_segment_1" pos="0.125 0 0" euler="0 0 0">
            <geom name="arm_3_segment_1_capsule" class="/" type="capsule" size="0.022499999999999999 0.032500000000000001" rgba="0.49019607843137253 0.70980392156862748 0.6588235294117647 1" pos="0.055 0 0" euler="0 1.5707963267948966 0"/>
            <geom name="arm_3_segment_1_connector" class="/" type="sphere" contype="0" conaffinity="0" size="0.01125" rgba="0.34901960784313724 0.34901960784313724 0.34901960784313724 1" pos="0 0 0"/>
            <joint name="arm_3_segment_1_in_plane_joint" class="/" type="hinge" axis="0 0 1" limited="true" stiffness="0.01" range="-0.52359877559829882 0.52359877559829882" armature="0.01" damping="0.10000000000000001"/>
            <joint name="arm_3_segment_1_out_of_plane_joint" class="/" type="hinge" axis="0 -1 0" limited="true" stiffness="0.01" range="-0.52359877559829882 0.52359877559829882" armature="0.01" damping="0.10000000000000001"/>
            <body name="arm_3_segment_2" pos="0.11 0 0" euler="0 0 0">
              <geom name="arm_3_segment_2_capsule" class="/" type="capsule" size="0.02 0.027499999999999997" rgba="0.49019607843137253 0.70980392156862748 0.6588235294117647 1" pos="0.047500000000000001 0 0" euler="0 1.5707963267948966 0"/>
              <geom name="arm_3_segment_2_connector" class="/" type="sphere" contype="0" conaffinity="0" size="0.01" rgba="0.34901960784313724 0.34901960784313724 0.34901960784313724 1" pos="0 0 0"/>
              <joint name="arm_3_segment_2_in_plane_joint" class="/" type="hinge" axis="0 0 1" limited="true" stiffness="0.01" range="-0.52359877559829882 0.52359877559829882" armature="0.01" damping="0.10000000000000001"/>
              <joint name="arm_3_segment_2_out_of_plane_joint" class="/" type="hinge" axis="0 -1 0" limited="true" stiffness="0.01" range="-0.52359877559829882 0.52359877559829882" armature="0.01" damping="0.10000000000000001"/>
              <body name="arm_3_segment_3" pos="0.095000000000000001 0 0" euler="0 0 0">
                <geom name="arm_3_segment_3_capsule" class="/" type="capsule" size="0.017500000000000002 0.022499999999999999" rgba="0.49019607843137253 0.70980392156862748 0.6588235294117647 1" pos="0.040000000000000001 0 0" euler="0 1.5707963267948966 0"/>
                <geom name="arm_3_segment_3_connector" class="/" type="sphere" contype="0" conaffinity="0" size="0.0087500000000000008" rgba="0.34901960784313724 0.34901960784313724 0.34901960784313724 1" pos="0 0 0"/>
                <joint name="arm_3_segment_3_in_plane_joint" class="/" type="hinge" axis="0 0 1" limited="true" stiffness="0.01" range="-0.52359877559829882 0.52359877559829882" armature="0.01" damping="0.10000000000000001"/>
                <joint name="arm_3_segment_3_out_of_plane_joint" class="/" type="hinge" axis="0 -1 0" limited="true" stiffness="0.01" range="-0.52359877559829882 0.52359877559829882" armature="0.01" damping="0.10000000000000001"/>
                <body name="arm_3_segment_4" pos="0.080000000000000002 0 0" euler="0 0 0">
                  <geom name="arm_3_segment_4_capsule" class="/" type="capsule" size="0.014999999999999999 0.017499999999999998" rgba="0.49019607843137253 0.70980392156862748 0.6588235294117647 1" pos="0.032500000000000001 0 0" euler="0 1.5707963267948966 0"/>
                  <geom name="arm_3_segment_4_connector" class="/" type="sphere" contype="0" conaffinity="0" size="0.0074999999999999997" rgba="0.34901960784313724 0.34901960784313724 0.34901960784313724 1" pos="0 0 0"/>
                  <joint name="arm_3_segment_4_in_plane_joint" class="/" type="hinge" axis="0 0 1" limited="true" stiffness="0.01" range="-0.52359877559829882 0.52359877559829882" armature="0.01" damping="0.10000000000000001"/>
                  <joint name="arm_3_segment_4_out_of_plane_joint" class="/" type="hinge" axis="0 -1 0" limited="true" stiffness="0.01" range="-0.52359877559829882 0.52359877559829882" armature="0.01" damping="0.10000000000000001"/>
                </body>
              </body>
            </body>
          </body>
        </body>
      </body>
      <body name="arm_4" pos="0.038627124296868404 -0.11888206453689421 0" euler="0 0 5.026548245743669">
        <body name="arm_4_segment_0" pos="0 0 0" euler="0 0 0">
          <geom name="arm_4_segment_0_capsule" class="/" type="capsule" size="0.025000000000000001 0.037499999999999999" rgba="0.49019607843137253 0.70980392156862748 0.6588235294117647 1" pos="0.0625 0 0" euler="0 1.5707963267948966 0"/>
          <geom name="arm_4_segment_0_connector" class="/" type="sphere" contype="0" conaffinity="0" size="0.012500000000000001" rgba="0.34901960784313724 0.34901960784313724 0.34901960784313724 1" pos="0 0 0"/>
          <joint name="arm_4_segment_0_in_plane_joint" class="/" type="hinge" axis="0 0 1" limited="true" stiffness="0.01" range="-0.52359877559829882 0.52359877559829882" armature="0.01" damping="0.10000000000000001"/>
          <joint name="arm_4_segment_0_out_of_plane_joint" class="/" type="hinge" axis="0 -1 0" limited="true" stiffness="0.01" range="-0.52359877559829882 0.52359877559829882" armature="0.01" damping="0.10000000000000001"/>
          <body name="arm_4_segment_1" pos="0.125 0 0" euler="0 0 0">
            <geom name="arm_4_segment_1_capsule" class="/" type="capsule" size="0.022499999999999999 0.032500000000000001" rgba="0.49019607843137253 0.70980392156862748 0.6588235294117647 1" pos="0.055 0 0" euler="0 1.5707963267948966 0"/>
            <geom name="arm_4_segment_1_connector" class="/" type="sphere" contype="0" conaffinity="0" size="0.01125" rgba="0.34901960784313724 0.34901960784313724 0.34901960784313724 1" pos="0 0 0"/>
            <joint name="arm_4_segment_1_in_plane_joint" class="/" type="hinge" axis="0 0 1" limited="true" stiffness="0.01" range="-0.52359877559829882 0.52359877559829882" armature="0.01" damping="0.10000000000000001"/>
            <joint name="arm_4_segment_1_out_of_plane_joint" class="/" type="hinge" axis="0 -1 0" limited="true" stiffness="0.01" range="-0.52359877559829882 0.52359877559829882" armature="0.01" damping="0.10000000000000001"/>
            <body name="arm_4_segment_2" pos="0.11 0 0" euler="0 0 0">
              <geom name="arm_4_segment_2_capsule" class="/" type="capsule" size="0.02 0.027499999999999997" rgba="0.49019607843137253 0.70980392156862748 0.6588235294117647 1" pos="0.047500000000000001 0 0" euler="0 1.5707963267948966 0"/>
              <geom name="arm_4_segment_2_connector" class="/" type="sphere" contype="0" conaffinity="0" size="0.01" rgba="0.34901960784313724 0.34901960784313724 0.34901960784313724 1" pos="0 0 0"/>
              <joint name="arm_4_segment_2_in_plane_joint" class="/" type="hinge" axis="0 0 1" limited="true" stiffness="0.01" range="-0.52359877559829882 0.52359877559829882" armature="0.01" damping="0.10000000000000001"/>
              <joint name="arm_4_segment_2_out_of_plane_joint" class="/" type="hinge" axis="0 -1 0" limited="true" stiffness="0.01" range="-0.52359877559829882 0.52359877559829882" armature="0.01" damping="0.10000000000000001"/>
              <body name="arm_4_segment_3" pos="0.095000000000000001 0 0" euler="0 0 0">
                <geom name="arm_4_segment_3_capsule" class="/" type="capsule" size="0.017500000000000002 0.022499999999999999" rgba="0.49019607843137253 0.70980392156862748 0.6588235294117647 1" pos="0.040000000000000001 0 0" euler="0 1.5707963267948966 0"/>
                <geom name="arm_4_segment_3_connector" class="/" type="sphere" contype="0" conaffinity="0" size="0.0087500000000000008" rgba="0.34901960784313724 0.34901960784313724 0.34901960784313724 1" pos="0 0 0"/>
                <joint name="arm_4_segment_3_in_plane_joint" class="/" type="hinge" axis="0 0 1" limited="true" stiffness="0.01" range="-0.52359877559829882 0.52359877559829882" armature="0.01" damping="0.10000000000000001"/>
                <joint name="arm_4_segment_3_out_of_plane_joint" class="/" type="hinge" axis="0 -1 0" limited="true" stiffness="0.01" range="-0.52359877559829882 0.52359877559829882" armature="0.01" damping="0.10000000000000001"/>
                <body name="arm_4_segment_4" pos="0.080000000000000002 0 0" euler="0 0 0">
                  <geom name="arm_4_segment_4_capsule" class="/" type="capsule" size="0.014999999999999999 0.017499999999999998" rgba="0.49019607843137253 0.70980392156862748 0.6588235294117647 1" pos="0.032500000000000001 0 0" euler="0 1.5707963267948966 0"/>
                  <geom name="arm_4_segment_4_connector" class="/" type="sphere" contype="0" conaffinity="0" size="0.0074999999999999997" rgba="0.34901960784313724 0.34901960784313724 0.34901960784313724 1" pos="0 0 0"/>
                  <joint name="arm_4_segment_4_in_plane_joint" class="/" type="hinge" axis="0 0 1" limited="true" stiffness="0.01" range="-0.52359877559829882 0.52359877559829882" armature="0.01" damping="0.10000000000000001"/>
                  <joint name="arm_4_segment_4_out_of_plane_joint" class="/" type="hinge" axis="0 -1 0" limited="true" stiffness="0.01" range="-0.52359877559829882 0.52359877559829882" armature="0.01" damping="0.10000000000000001"/>
                </body>
              </body>
            </body>
          </body>
        </body>
      </body>
      <camera name="side_camera" class="/" mode="track" pos="0 -2 2.5" quat="0.93969262078590843 0.34202014332566871 0 0"/>
    </body>
  </worldbody>
  <actuator>
    <motor name="arm_0_segment_0_in_plane_joint_torque_control" class="/" ctrllimited="true" forcelimited="true" ctrlrange="-5 5" forcerange="-5 5" joint="arm_0_segment_0_in_plane_joint"/>
    <motor name="arm_0_segment_0_out_of_plane_joint_torque_control" class="/" ctrllimited="true" forcelimited="true" ctrlrange="-5 5" forcerange="-5 5" joint="arm_0_segment_0_out_of_plane_joint"/>
    <motor name="arm_0_segment_1_in_plane_joint_torque_control" class="/" ctrllimited="true" forcelimited="true" ctrlrange="-4.5 4.5" forcerange="-4.5 4.5" joint="arm_0_segment_1_in_plane_joint"/>
    <motor name="arm_0_segment_1_out_of_plane_joint_torque_control" class="/" ctrllimited="true" forcelimited="true" ctrlrange="-4.5 4.5" forcerange="-4.5 4.5" joint="arm_0_segment_1_out_of_plane_joint"/>
    <motor name="arm_0_segment_2_in_plane_joint_torque_control" class="/" ctrllimited="true" forcelimited="true" ctrlrange="-4 4" forcerange="-4 4" joint="arm_0_segment_2_in_plane_joint"/>
    <motor name="arm_0_segment_2_out_of_plane_joint_torque_control" class="/" ctrllimited="true" forcelimited="true" ctrlrange="-4 4" forcerange="-4 4" joint="arm_0_segment_2_out_of_plane_joint"/>
    <motor name="arm_0_segment_3_in_plane_joint_torque_control" class="/" ctrllimited="true" forcelimited="true" ctrlrange="-3.5000000000000004 3.5000000000000004" forcerange="-3.5000000000000004 3.5000000000000004" joint="arm_0_segment_3_in_plane_joint"/>
    <motor name="arm_0_segment_3_out_of_plane_joint_torque_control" class="/" ctrllimited="true" forcelimited="true" ctrlrange="-3.5000000000000004 3.5000000000000004" forcerange="-3.5000000000000004 3.5000000000000004" joint="arm_0_segment_3_out_of_plane_joint"/>
    <motor name="arm_0_segment_4_in_plane_joint_torque_control" class="/" ctrllimited="true" forcelimited="true" ctrlrange="-3 3" forcerange="-3 3" joint="arm_0_segment_4_in_plane_joint"/>
    <motor name="arm_0_segment_4_out_of_plane_joint_torque_control" class="/" ctrllimited="true" forcelimited="true" ctrlrange="-3 3" forcerange="-3 3" joint="arm_0_segment_4_out_of_plane_joint"/>
    <motor name="arm_1_segment_0_in_plane_joint_torque_control" class="/" ctrllimited="true" forcelimited="true" ctrlrange="-5 5" forcerange="-5 5" joint="arm_1_segment_0_in_plane_joint"/>
    <motor name="arm_1_segment_0_out_of_plane_joint_torque_control" class="/" ctrllimited="true" forcelimited="true" ctrlrange="-5 5" forcerange="-5 5" joint="arm_1_segment_0_out_of_plane_joint"/>
    <motor name="arm_1_segment_1_in_plane_joint_torque_control" class="/" ctrllimited="true" forcelimited="true" ctrlrange="-4.5 4.5" forcerange="-4.5 4.5" joint="arm_1_segment_1_in_plane_joint"/>
    <motor name="arm_1_segment_1_out_of_plane_joint_torque_control" class="/" ctrllimited="true" forcelimited="true" ctrlrange="-4.5 4.5" forcerange="-4.5 4.5" joint="arm_1_segment_1_out_of_plane_joint"/>
    <motor name="arm_1_segment_2_in_plane_joint_torque_control" class="/" ctrllimited="true" forcelimited="true" ctrlrange="-4 4" forcerange="-4 4" joint="arm_1_segment_2_in_plane_joint"/>
    <motor name="arm_1_segment_2_out_of_plane_joint_torque_control" class="/" ctrllimited="true" forcelimited="true" ctrlrange="-4 4" forcerange="-4 4" joint="arm_1_segment_2_out_of_plane_joint"/>
    <motor name="arm_1_segment_3_in_plane_joint_torque_control" class="/" ctrllimited="true" forcelimited="true" ctrlrange="-3.5000000000000004 3.5000000000000004" forcerange="-3.5000000000000004 3.5000000000000004" joint="arm_1_segment_3_in_plane_joint"/>
    <motor name="arm_1_segment_3_out_of_plane_joint_torque_control" class="/" ctrllimited="true" forcelimited="true" ctrlrange="-3.5000000000000004 3.5000000000000004" forcerange="-3.5000000000000004 3.5000000000000004" joint="arm_1_segment_3_out_of_plane_joint"/>
    <motor name="arm_1_segment_4_in_plane_joint_torque_control" class="/" ctrllimited="true" forcelimited="true" ctrlrange="-3 3" forcerange="-3 3" joint="arm_1_segment_4_in_plane_joint"/>
    <motor name="arm_1_segment_4_out_of_plane_joint_torque_control" class="/" ctrllimited="true" forcelimited="true" ctrlrange="-3 3" forcerange="-3 3" joint="arm_1_segment_4_out_of_plane_joint"/>
    <motor name="arm_2_segment_0_in_plane_joint_torque_control" class="/" ctrllimited="true" forcelimited="true" ctrlrange="-5 5" forcerange="-5 5" joint="arm_2_segment_0_in_plane_joint"/>
    <motor name="arm_2_segment_0_out_of_plane_joint_torque_control" class="/" ctrllimited="true" forcelimited="true" ctrlrange="-5 5" forcerange="-5 5" joint="arm_2_segment_0_out_of_plane_joint"/>
    <motor name="arm_2_segment_1_in_plane_joint_torque_control" class="/" ctrllimited="true" forcelimited="true" ctrlrange="-4.5 4.5" forcerange="-4.5 4.5" joint="arm_2_segment_1_in_plane_joint"/>
    <motor name="arm_2_segment_1_out_of_plane_joint_torque_control" class="/" ctrllimited="true" forcelimited="true" ctrlrange="-4.5 4.5" forcerange="-4.5 4.5" joint="arm_2_segment_1_out_of_plane_joint"/>
    <motor name="arm_2_segment_2_in_plane_joint_torque_control" class="/" ctrllimited="true" forcelimited="true" ctrlrange="-4 4" forcerange="-4 4" joint="arm_2_segment_2_in_plane_joint"/>
    <motor name="arm_2_segment_2_out_of_plane_joint_torque_control" class="/" ctrllimited="true" forcelimited="true" ctrlrange="-4 4" forcerange="-4 4" joint="arm_2_segment_2_out_of_plane_joint"/>
    <motor name="arm_2_segment_3_in_plane_joint_torque_control" class="/" ctrllimited="true" forcelimited="true" ctrlrange="-3.5000000000000004 3.5000000000000004" forcerange="-3.5000000000000004 3.5000000000000004" joint="arm_2_segment_3_in_plane_joint"/>
    <motor name="arm_2_segment_3_out_of_plane_joint_torque_control" class="/" ctrllimited="true" forcelimited="true" ctrlrange="-3.5000000000000004 3.5000000000000004" forcerange="-3.5000000000000004 3.5000000000000004" joint="arm_2_segment_3_out_of_plane_joint"/>
    <motor name="arm_2_segment_4_in_plane_joint_torque_control" class="/" ctrllimited="true" forcelimited="true" ctrlrange="-3 3" forcerange="-3 3" joint="arm_2_segment_4_in_plane_joint"/>
    <motor name="arm_2_segment_4_out_of_plane_joint_torque_control" class="/" ctrllimited="true" forcelimited="true" ctrlrange="-3 3" forcerange="-3 3" joint="arm_2_segment_4_out_of_plane_joint"/>
    <motor name="arm_3_segment_0_in_plane_joint_torque_control" class="/" ctrllimited="true" forcelimited="true" ctrlrange="-5 5" forcerange="-5 5" joint="arm_3_segment_0_in_plane_joint"/>
    <motor name="arm_3_segment_0_out_of_plane_joint_torque_control" class="/" ctrllimited="true" forcelimited="true" ctrlrange="-5 5" forcerange="-5 5" joint="arm_3_segment_0_out_of_plane_joint"/>
    <motor name="arm_3_segment_1_in_plane_joint_torque_control" class="/" ctrllimited="true" forcelimited="true" ctrlrange="-4.5 4.5" forcerange="-4.5 4.5" joint="arm_3_segment_1_in_plane_joint"/>
    <motor name="arm_3_segment_1_out_of_plane_joint_torque_control" class="/" ctrllimited="true" forcelimited="true" ctrlrange="-4.5 4.5" forcerange="-4.5 4.5" joint="arm_3_segment_1_out_of_plane_joint"/>
    <motor name="arm_3_segment_2_in_plane_joint_torque_control" class="/" ctrllimited="true" forcelimited="true" ctrlrange="-4 4" forcerange="-4 4" joint="arm_3_segment_2_in_plane_joint"/>
    <motor name="arm_3_segment_2_out_of_plane_joint_torque_control" class="/" ctrllimited="true" forcelimited="true" ctrlrange="-4 4" forcerange="-4 4" joint="arm_3_segment_2_out_of_plane_joint"/>
    <motor name="arm_3_segment_3_in_plane_joint_torque_control" class="/" ctrllimited="true" forcelimited="true" ctrlrange="-3.5000000000000004 3.5000000000000004" forcerange="-3.5000000000000004 3.5000000000000004" joint="arm_3_segment_3_in_plane_joint"/>
    <motor name="arm_3_segment_3_out_of_plane_joint_torque_control" class="/" ctrllimited="true" forcelimited="true" ctrlrange="-3.5000000000000004 3.5000000000000004" forcerange="-3.5000000000000004 3.5000000000000004" joint="arm_3_segment_3_out_of_plane_joint"/>
    <motor name="arm_3_segment_4_in_plane_joint_torque_control" class="/" ctrllimited="true" forcelimited="true" ctrlrange="-3 3" forcerange="-3 3" joint="arm_3_segment_4_in_plane_joint"/>
    <motor name="arm_3_segment_4_out_of_plane_joint_torque_control" class="/" ctrllimited="true" forcelimited="true" ctrlrange="-3 3" forcerange="-3 3" joint="arm_3_segment_4_out_of_plane_joint"/>
    <motor name="arm_4_segment_0_in_plane_joint_torque_control" class="/" ctrllimited="true" forcelimited="true" ctrlrange="-5 5" forcerange="-5 5" joint="arm_4_segment_0_in_plane_joint"/>
    <motor name="arm_4_segment_0_out_of_plane_joint_torque_control" class="/" ctrllimited="true" forcelimited="true" ctrlrange="-5 5" forcerange="-5 5" joint="arm_4_segment_0_out_of_plane_joint"/>
    <motor name="arm_4_segment_1_in_plane_joint_torque_control" class="/" ctrllimited="true" forcelimited="true" ctrlrange="-4.5 4.5" forcerange="-4.5 4.5" joint="arm_4_segment_1_in_plane_joint"/>
    <motor name="arm_4_segment_1_out_of_plane_joint_torque_control" class="/" ctrllimited="true" forcelimited="true" ctrlrange="-4.5 4.5" forcerange="-4.5 4.5" joint="arm_4_segment_1_out_of_plane_joint"/>
    <motor name="arm_4_segment_2_in_plane_joint_torque_control" class="/" ctrllimited="true" forcelimited="true" ctrlrange="-4 4" forcerange="-4 4" joint="arm_4_segment_2_in_plane_joint"/>
    <motor name="arm_4_segment_2_out_of_plane_joint_torque_control" class="/" ctrllimited="true" forcelimited="true" ctrlrange="-4 4" forcerange="-4 4" joint="arm_4_segment_2_out_of_plane_joint"/>
    <motor name="arm_4_segment_3_in_plane_joint_torque_control" class="/" ctrllimited="true" forcelimited="true" ctrlrange="-3.5000000000000004 3.5000000000000004" forcerange="-3.5000000000000004 3.5000000000000004" joint="arm_4_segment_3_in_plane_joint"/>
    <motor name="arm_4_segment_3_out_of_plane_joint_torque_control" class="/" ctrllimited="true" forcelimited="true" ctrlrange="-3.5000000000000004 3.5000000000000004" forcerange="-3.5000000000000004 3.5000000000000004" joint="arm_4_segment_3_out_of_plane_joint"/>
    <motor name="arm_4_segment_4_in_plane_joint_torque_control" class="/" ctrllimited="true" forcelimited="true" ctrlrange="-3 3" forcerange="-3 3" joint="arm_4_segment_4_in_plane_joint"/>
    <motor name="arm_4_segment_4_out_of_plane_joint_torque_control" class="/" ctrllimited="true" forcelimited="true" ctrlrange="-3 3" forcerange="-3 3" joint="arm_4_segment_4_out_of_plane_joint"/>
  </actuator>
  <sensor>
    <framepos name="arm_0_segment_0_position_sensor" objtype="geom" objname="arm_0_segment_0_capsule"/>
    <jointpos name="arm_0_segment_0_in_plane_joint_jointpos_sensor" joint="arm_0_segment_0_in_plane_joint"/>
    <jointvel name="arm_0_segment_0_in_plane_joint_jointvel_sensor" joint="arm_0_segment_0_in_plane_joint"/>
    <jointactuatorfrc name="arm_0_segment_0_in_plane_joint_actuatorfrc_sensor" joint="arm_0_segment_0_in_plane_joint"/>
    <jointpos name="arm_0_segment_0_out_of_plane_joint_jointpos_sensor" joint="arm_0_segment_0_out_of_plane_joint"/>
    <jointvel name="arm_0_segment_0_out_of_plane_joint_jointvel_sensor" joint="arm_0_segment_0_out_of_plane_joint"/>
    <jointactuatorfrc name="arm_0_segment_0_out_of_plane_joint_actuatorfrc_sensor" joint="arm_0_segment_0_out_of_plane_joint"/>
    <actuatorfrc name="arm_0_segment_0_in_plane_joint_torque_control_actuatorfrc_sensor" actuator="arm_0_segment_0_in_plane_joint_torque_control"/>
    <actuatorfrc name="arm_0_segment_0_out_of_plane_joint_torque_control_actuatorfrc_sensor" actuator="arm_0_segment_0_out_of_plane_joint_torque_control"/>
    <framepos name="arm_0_segment_1_position_sensor" objtype="geom" objname="arm_0_segment_1_capsule"/>
    <jointpos name="arm_0_segment_1_in_plane_joint_jointpos_sensor" joint="arm_0_segment_1_in_plane_joint"/>
    <jointvel name="arm_0_segment_1_in_plane_joint_jointvel_sensor" joint="arm_0_segment_1_in_plane_joint"/>
    <jointactuatorfrc name="arm_0_segment_1_in_plane_joint_actuatorfrc_sensor" joint="arm_0_segment_1_in_plane_joint"/>
    <jointpos name="arm_0_segment_1_out_of_plane_joint_jointpos_sensor" joint="arm_0_segment_1_out_of_plane_joint"/>
    <jointvel name="arm_0_segment_1_out_of_plane_joint_jointvel_sensor" joint="arm_0_segment_1_out_of_plane_joint"/>
    <jointactuatorfrc name="arm_0_segment_1_out_of_plane_joint_actuatorfrc_sensor" joint="arm_0_segment_1_out_of_plane_joint"/>
    <actuatorfrc name="arm_0_segment_1_in_plane_joint_torque_control_actuatorfrc_sensor" actuator="arm_0_segment_1_in_plane_joint_torque_control"/>
    <actuatorfrc name="arm_0_segment_1_out_of_plane_joint_torque_control_actuatorfrc_sensor" actuator="arm_0_segment_1_out_of_plane_joint_torque_control"/>
    <framepos name="arm_0_segment_2_position_sensor" objtype="geom" objname="arm_0_segment_2_capsule"/>
    <jointpos name="arm_0_segment_2_in_plane_joint_jointpos_sensor" joint="arm_0_segment_2_in_plane_joint"/>
    <jointvel name="arm_0_segment_2_in_plane_joint_jointvel_sensor" joint="arm_0_segment_2_in_plane_joint"/>
    <jointactuatorfrc name="arm_0_segment_2_in_plane_joint_actuatorfrc_sensor" joint="arm_0_segment_2_in_plane_joint"/>
    <jointpos name="arm_0_segment_2_out_of_plane_joint_jointpos_sensor" joint="arm_0_segment_2_out_of_plane_joint"/>
    <jointvel name="arm_0_segment_2_out_of_plane_joint_jointvel_sensor" joint="arm_0_segment_2_out_of_plane_joint"/>
    <jointactuatorfrc name="arm_0_segment_2_out_of_plane_joint_actuatorfrc_sensor" joint="arm_0_segment_2_out_of_plane_joint"/>
    <actuatorfrc name="arm_0_segment_2_in_plane_joint_torque_control_actuatorfrc_sensor" actuator="arm_0_segment_2_in_plane_joint_torque_control"/>
    <actuatorfrc name="arm_0_segment_2_out_of_plane_joint_torque_control_actuatorfrc_sensor" actuator="arm_0_segment_2_out_of_plane_joint_torque_control"/>
    <framepos name="arm_0_segment_3_position_sensor" objtype="geom" objname="arm_0_segment_3_capsule"/>
    <jointpos name="arm_0_segment_3_in_plane_joint_jointpos_sensor" joint="arm_0_segment_3_in_plane_joint"/>
    <jointvel name="arm_0_segment_3_in_plane_joint_jointvel_sensor" joint="arm_0_segment_3_in_plane_joint"/>
    <jointactuatorfrc name="arm_0_segment_3_in_plane_joint_actuatorfrc_sensor" joint="arm_0_segment_3_in_plane_joint"/>
    <jointpos name="arm_0_segment_3_out_of_plane_joint_jointpos_sensor" joint="arm_0_segment_3_out_of_plane_joint"/>
    <jointvel name="arm_0_segment_3_out_of_plane_joint_jointvel_sensor" joint="arm_0_segment_3_out_of_plane_joint"/>
    <jointactuatorfrc name="arm_0_segment_3_out_of_plane_joint_actuatorfrc_sensor" joint="arm_0_segment_3_out_of_plane_joint"/>
    <actuatorfrc name="arm_0_segment_3_in_plane_joint_torque_control_actuatorfrc_sensor" actuator="arm_0_segment_3_in_plane_joint_torque_control"/>
    <actuatorfrc name="arm_0_segment_3_out_of_plane_joint_torque_control_actuatorfrc_sensor" actuator="arm_0_segment_3_out_of_plane_joint_torque_control"/>
    <framepos name="arm_0_segment_4_position_sensor" objtype="geom" objname="arm_0_segment_4_capsule"/>
    <jointpos name="arm_0_segment_4_in_plane_joint_jointpos_sensor" joint="arm_0_segment_4_in_plane_joint"/>
    <jointvel name="arm_0_segment_4_in_plane_joint_jointvel_sensor" joint="arm_0_segment_4_in_plane_joint"/>
    <jointactuatorfrc name="arm_0_segment_4_in_plane_joint_actuatorfrc_sensor" joint="arm_0_segment_4_in_plane_joint"/>
    <jointpos name="arm_0_segment_4_out_of_plane_joint_jointpos_sensor" joint="arm_0_segment_4_out_of_plane_joint"/>
    <jointvel name="arm_0_segment_4_out_of_plane_joint_jointvel_sensor" joint="arm_0_segment_4_out_of_plane_joint"/>
    <jointactuatorfrc name="arm_0_segment_4_out_of_plane_joint_actuatorfrc_sensor" joint="arm_0_segment_4_out_of_plane_joint"/>
    <actuatorfrc name="arm_0_segment_4_in_plane_joint_torque_control_actuatorfrc_sensor" actuator="arm_0_segment_4_in_plane_joint_torque_control"/>
    <actuatorfrc name="arm_0_segment_4_out_of_plane_joint_torque_control_actuatorfrc_sensor" actuator="arm_0_segment_4_out_of_plane_joint_torque_control"/>
    <framepos name="arm_1_segment_0_position_sensor" objtype="geom" objname="arm_1_segment_0_capsule"/>
    <jointpos name="arm_1_segment_0_in_plane_joint_jointpos_sensor" joint="arm_1_segment_0_in_plane_joint"/>
    <jointvel name="arm_1_segment_0_in_plane_joint_jointvel_sensor" joint="arm_1_segment_0_in_plane_joint"/>
    <jointactuatorfrc name="arm_1_segment_0_in_plane_joint_actuatorfrc_sensor" joint="arm_1_segment_0_in_plane_joint"/>
    <jointpos name="arm_1_segment_0_out_of_plane_joint_jointpos_sensor" joint="arm_1_segment_0_out_of_plane_joint"/>
    <jointvel name="arm_1_segment_0_out_of_plane_joint_jointvel_sensor" joint="arm_1_segment_0_out_of_plane_joint"/>
    <jointactuatorfrc name="arm_1_segment_0_out_of_plane_joint_actuatorfrc_sensor" joint="arm_1_segment_0_out_of_plane_joint"/>
    <actuatorfrc name="arm_1_segment_0_in_plane_joint_torque_control_actuatorfrc_sensor" actuator="arm_1_segment_0_in_plane_joint_torque_control"/>
    <actuatorfrc name="arm_1_segment_0_out_of_plane_joint_torque_control_actuatorfrc_sensor" actuator="arm_1_segment_0_out_of_plane_joint_torque_control"/>
    <framepos name="arm_1_segment_1_position_sensor" objtype="geom" objname="arm_1_segment_1_capsule"/>
    <jointpos name="arm_1_segment_1_in_plane_joint_jointpos_sensor" joint="arm_1_segment_1_in_plane_joint"/>
    <jointvel name="arm_1_segment_1_in_plane_joint_jointvel_sensor" joint="arm_1_segment_1_in_plane_joint"/>
    <jointactuatorfrc name="arm_1_segment_1_in_plane_joint_actuatorfrc_sensor" joint="arm_1_segment_1_in_plane_joint"/>
    <jointpos name="arm_1_segment_1_out_of_plane_joint_jointpos_sensor" joint="arm_1_segment_1_out_of_plane_joint"/>
    <jointvel name="arm_1_segment_1_out_of_plane_joint_jointvel_sensor" joint="arm_1_segment_1_out_of_plane_joint"/>
    <jointactuatorfrc name="arm_1_segment_1_out_of_plane_joint_actuatorfrc_sensor" joint="arm_1_segment_1_out_of_plane_joint"/>
    <actuatorfrc name="arm_1_segment_1_in_plane_joint_torque_control_actuatorfrc_sensor" actuator="arm_1_segment_1_in_plane_joint_torque_control"/>
    <actuatorfrc name="arm_1_segment_1_out_of_plane_joint_torque_control_actuatorfrc_sensor" actuator="arm_1_segment_1_out_of_plane_joint_torque_control"/>
    <framepos name="arm_1_segment_2_position_sensor" objtype="geom" objname="arm_1_segment_2_capsule"/>
    <jointpos name="arm_1_segment_2_in_plane_joint_jointpos_sensor" joint="arm_1_segment_2_in_plane_joint"/>
    <jointvel name="arm_1_segment_2_in_plane_joint_jointvel_sensor" joint="arm_1_segment_2_in_plane_joint"/>
    <jointactuatorfrc name="arm_1_segment_2_in_plane_joint_actuatorfrc_sensor" joint="arm_1_segment_2_in_plane_joint"/>
    <jointpos name="arm_1_segment_2_out_of_plane_joint_jointpos_sensor" joint="arm_1_segment_2_out_of_plane_joint"/>
    <jointvel name="arm_1_segment_2_out_of_plane_joint_jointvel_sensor" joint="arm_1_segment_2_out_of_plane_joint"/>
    <jointactuatorfrc name="arm_1_segment_2_out_of_plane_joint_actuatorfrc_sensor" joint="arm_1_segment_2_out_of_plane_joint"/>
    <actuatorfrc name="arm_1_segment_2_in_plane_joint_torque_control_actuatorfrc_sensor" actuator="arm_1_segment_2_in_plane_joint_torque_control"/>
    <actuatorfrc name="arm_1_segment_2_out_of_plane_joint_torque_control_actuatorfrc_sensor" actuator="arm_1_segment_2_out_of_plane_joint_torque_control"/>
    <framepos name="arm_1_segment_3_position_sensor" objtype="geom" objname="arm_1_segment_3_capsule"/>
    <jointpos name="arm_1_segment_3_in_plane_joint_jointpos_sensor" joint="arm_1_segment_3_in_plane_joint"/>
    <jointvel name="arm_1_segment_3_in_plane_joint_jointvel_sensor" joint="arm_1_segment_3_in_plane_joint"/>
    <jointactuatorfrc name="arm_1_segment_3_in_plane_joint_actuatorfrc_sensor" joint="arm_1_segment_3_in_plane_joint"/>
    <jointpos name="arm_1_segment_3_out_of_plane_joint_jointpos_sensor" joint="arm_1_segment_3_out_of_plane_joint"/>
    <jointvel name="arm_1_segment_3_out_of_plane_joint_jointvel_sensor" joint="arm_1_segment_3_out_of_plane_joint"/>
    <jointactuatorfrc name="arm_1_segment_3_out_of_plane_joint_actuatorfrc_sensor" joint="arm_1_segment_3_out_of_plane_joint"/>
    <actuatorfrc name="arm_1_segment_3_in_plane_joint_torque_control_actuatorfrc_sensor" actuator="arm_1_segment_3_in_plane_joint_torque_control"/>
    <actuatorfrc name="arm_1_segment_3_out_of_plane_joint_torque_control_actuatorfrc_sensor" actuator="arm_1_segment_3_out_of_plane_joint_torque_control"/>
    <framepos name="arm_1_segment_4_position_sensor" objtype="geom" objname="arm_1_segment_4_capsule"/>
    <jointpos name="arm_1_segment_4_in_plane_joint_jointpos_sensor" joint="arm_1_segment_4_in_plane_joint"/>
    <jointvel name="arm_1_segment_4_in_plane_joint_jointvel_sensor" joint="arm_1_segment_4_in_plane_joint"/>
    <jointactuatorfrc name="arm_1_segment_4_in_plane_joint_actuatorfrc_sensor" joint="arm_1_segment_4_in_plane_joint"/>
    <jointpos name="arm_1_segment_4_out_of_plane_joint_jointpos_sensor" joint="arm_1_segment_4_out_of_plane_joint"/>
    <jointvel name="arm_1_segment_4_out_of_plane_joint_jointvel_sensor" joint="arm_1_segment_4_out_of_plane_joint"/>
    <jointactuatorfrc name="arm_1_segment_4_out_of_plane_joint_actuatorfrc_sensor" joint="arm_1_segment_4_out_of_plane_joint"/>
    <actuatorfrc name="arm_1_segment_4_in_plane_joint_torque_control_actuatorfrc_sensor" actuator="arm_1_segment_4_in_plane_joint_torque_control"/>
    <actuatorfrc name="arm_1_segment_4_out_of_plane_joint_torque_control_actuatorfrc_sensor" actuator="arm_1_segment_4_out_of_plane_joint_torque_control"/>
    <framepos name="arm_2_segment_0_position_sensor" objtype="geom" objname="arm_2_segment_0_capsule"/>
    <jointpos name="arm_2_segment_0_in_plane_joint_jointpos_sensor" joint="arm_2_segment_0_in_plane_joint"/>
    <jointvel name="arm_2_segment_0_in_plane_joint_jointvel_sensor" joint="arm_2_segment_0_in_plane_joint"/>
    <jointactuatorfrc name="arm_2_segment_0_in_plane_joint_actuatorfrc_sensor" joint="arm_2_segment_0_in_plane_joint"/>
    <jointpos name="arm_2_segment_0_out_of_plane_joint_jointpos_sensor" joint="arm_2_segment_0_out_of_plane_joint"/>
    <jointvel name="arm_2_segment_0_out_of_plane_joint_jointvel_sensor" joint="arm_2_segment_0_out_of_plane_joint"/>
    <jointactuatorfrc name="arm_2_segment_0_out_of_plane_joint_actuatorfrc_sensor" joint="arm_2_segment_0_out_of_plane_joint"/>
    <actuatorfrc name="arm_2_segment_0_in_plane_joint_torque_control_actuatorfrc_sensor" actuator="arm_2_segment_0_in_plane_joint_torque_control"/>
    <actuatorfrc name="arm_2_segment_0_out_of_plane_joint_torque_control_actuatorfrc_sensor" actuator="arm_2_segment_0_out_of_plane_joint_torque_control"/>
    <framepos name="arm_2_segment_1_position_sensor" objtype="geom" objname="arm_2_segment_1_capsule"/>
    <jointpos name="arm_2_segment_1_in_plane_joint_jointpos_sensor" joint="arm_2_segment_1_in_plane_joint"/>
    <jointvel name="arm_2_segment_1_in_plane_joint_jointvel_sensor" joint="arm_2_segment_1_in_plane_joint"/>
    <jointactuatorfrc name="arm_2_segment_1_in_plane_joint_actuatorfrc_sensor" joint="arm_2_segment_1_in_plane_joint"/>
    <jointpos name="arm_2_segment_1_out_of_plane_joint_jointpos_sensor" joint="arm_2_segment_1_out_of_plane_joint"/>
    <jointvel name="arm_2_segment_1_out_of_plane_joint_jointvel_sensor" joint="arm_2_segment_1_out_of_plane_joint"/>
    <jointactuatorfrc name="arm_2_segment_1_out_of_plane_joint_actuatorfrc_sensor" joint="arm_2_segment_1_out_of_plane_joint"/>
    <actuatorfrc name="arm_2_segment_1_in_plane_joint_torque_control_actuatorfrc_sensor" actuator="arm_2_segment_1_in_plane_joint_torque_control"/>
    <actuatorfrc name="arm_2_segment_1_out_of_plane_joint_torque_control_actuatorfrc_sensor" actuator="arm_2_segment_1_out_of_plane_joint_torque_control"/>
    <framepos name="arm_2_segment_2_position_sensor" objtype="geom" objname="arm_2_segment_2_capsule"/>
    <jointpos name="arm_2_segment_2_in_plane_joint_jointpos_sensor" joint="arm_2_segment_2_in_plane_joint"/>
    <jointvel name="arm_2_segment_2_in_plane_joint_jointvel_sensor" joint="arm_2_segment_2_in_plane_joint"/>
    <jointactuatorfrc name="arm_2_segment_2_in_plane_joint_actuatorfrc_sensor" joint="arm_2_segment_2_in_plane_joint"/>
    <jointpos name="arm_2_segment_2_out_of_plane_joint_jointpos_sensor" joint="arm_2_segment_2_out_of_plane_joint"/>
    <jointvel name="arm_2_segment_2_out_of_plane_joint_jointvel_sensor" joint="arm_2_segment_2_out_of_plane_joint"/>
    <jointactuatorfrc name="arm_2_segment_2_out_of_plane_joint_actuatorfrc_sensor" joint="arm_2_segment_2_out_of_plane_joint"/>
    <actuatorfrc name="arm_2_segment_2_in_plane_joint_torque_control_actuatorfrc_sensor" actuator="arm_2_segment_2_in_plane_joint_torque_control"/>
    <actuatorfrc name="arm_2_segment_2_out_of_plane_joint_torque_control_actuatorfrc_sensor" actuator="arm_2_segment_2_out_of_plane_joint_torque_control"/>
    <framepos name="arm_2_segment_3_position_sensor" objtype="geom" objname="arm_2_segment_3_capsule"/>
    <jointpos name="arm_2_segment_3_in_plane_joint_jointpos_sensor" joint="arm_2_segment_3_in_plane_joint"/>
    <jointvel name="arm_2_segment_3_in_plane_joint_jointvel_sensor" joint="arm_2_segment_3_in_plane_joint"/>
    <jointactuatorfrc name="arm_2_segment_3_in_plane_joint_actuatorfrc_sensor" joint="arm_2_segment_3_in_plane_joint"/>
    <jointpos name="arm_2_segment_3_out_of_plane_joint_jointpos_sensor" joint="arm_2_segment_3_out_of_plane_joint"/>
    <jointvel name="arm_2_segment_3_out_of_plane_joint_jointvel_sensor" joint="arm_2_segment_3_out_of_plane_joint"/>
    <jointactuatorfrc name="arm_2_segment_3_out_of_plane_joint_actuatorfrc_sensor" joint="arm_2_segment_3_out_of_plane_joint"/>
    <actuatorfrc name="arm_2_segment_3_in_plane_joint_torque_control_actuatorfrc_sensor" actuator="arm_2_segment_3_in_plane_joint_torque_control"/>
    <actuatorfrc name="arm_2_segment_3_out_of_plane_joint_torque_control_actuatorfrc_sensor" actuator="arm_2_segment_3_out_of_plane_joint_torque_control"/>
    <framepos name="arm_2_segment_4_position_sensor" objtype="geom" objname="arm_2_segment_4_capsule"/>
    <jointpos name="arm_2_segment_4_in_plane_joint_jointpos_sensor" joint="arm_2_segment_4_in_plane_joint"/>
    <jointvel name="arm_2_segment_4_in_plane_joint_jointvel_sensor" joint="arm_2_segment_4_in_plane_joint"/>
    <jointactuatorfrc name="arm_2_segment_4_in_plane_joint_actuatorfrc_sensor" joint="arm_2_segment_4_in_plane_joint"/>
    <jointpos name="arm_2_segment_4_out_of_plane_joint_jointpos_sensor" joint="arm_2_segment_4_out_of_plane_joint"/>
    <jointvel name="arm_2_segment_4_out_of_plane_joint_jointvel_sensor" joint="arm_2_segment_4_out_of_plane_joint"/>
    <jointactuatorfrc name="arm_2_segment_4_out_of_plane_joint_actuatorfrc_sensor" joint="arm_2_segment_4_out_of_plane_joint"/>
    <actuatorfrc name="arm_2_segment_4_in_plane_joint_torque_control_actuatorfrc_sensor" actuator="arm_2_segment_4_in_plane_joint_torque_control"/>
    <actuatorfrc name="arm_2_segment_4_out_of_plane_joint_torque_control_actuatorfrc_sensor" actuator="arm_2_segment_4_out_of_plane_joint_torque_control"/>
    <framepos name="arm_3_segment_0_position_sensor" objtype="geom" objname="arm_3_segment_0_capsule"/>
    <jointpos name="arm_3_segment_0_in_plane_joint_jointpos_sensor" joint="arm_3_segment_0_in_plane_joint"/>
    <jointvel name="arm_3_segment_0_in_plane_joint_jointvel_sensor" joint="arm_3_segment_0_in_plane_joint"/>
    <jointactuatorfrc name="arm_3_segment_0_in_plane_joint_actuatorfrc_sensor" joint="arm_3_segment_0_in_plane_joint"/>
    <jointpos name="arm_3_segment_0_out_of_plane_joint_jointpos_sensor" joint="arm_3_segment_0_out_of_plane_joint"/>
    <jointvel name="arm_3_segment_0_out_of_plane_joint_jointvel_sensor" joint="arm_3_segment_0_out_of_plane_joint"/>
    <jointactuatorfrc name="arm_3_segment_0_out_of_plane_joint_actuatorfrc_sensor" joint="arm_3_segment_0_out_of_plane_joint"/>
    <actuatorfrc name="arm_3_segment_0_in_plane_joint_torque_control_actuatorfrc_sensor" actuator="arm_3_segment_0_in_plane_joint_torque_control"/>
    <actuatorfrc name="arm_3_segment_0_out_of_plane_joint_torque_control_actuatorfrc_sensor" actuator="arm_3_segment_0_out_of_plane_joint_torque_control"/>
    <framepos name="arm_3_segment_1_position_sensor" objtype="geom" objname="arm_3_segment_1_capsule"/>
    <jointpos name="arm_3_segment_1_in_plane_joint_jointpos_sensor" joint="arm_3_segment_1_in_plane_joint"/>
    <jointvel name="arm_3_segment_1_in_plane_joint_jointvel_sensor" joint="arm_3_segment_1_in_plane_joint"/>
    <jointactuatorfrc name="arm_3_segment_1_in_plane_joint_actuatorfrc_sensor" joint="arm_3_segment_1_in_plane_joint"/>
    <jointpos name="arm_3_segment_1_out_of_plane_joint_jointpos_sensor" joint="arm_3_segment_1_out_of_plane_joint"/>
    <jointvel name="arm_3_segment_1_out_of_plane_joint_jointvel_sensor" joint="arm_3_segment_1_out_of_plane_joint"/>
    <jointactuatorfrc name="arm_3_segment_1_out_of_plane_joint_actuatorfrc_sensor" joint="arm_3_segment_1_out_of_plane_joint"/>
    <actuatorfrc name="arm_3_segment_1_in_plane_joint_torque_control_actuatorfrc_sensor" actuator="arm_3_segment_1_in_plane_joint_torque_control"/>
    <actuatorfrc name="arm_3_segment_1_out_of_plane_joint_torque_control_actuatorfrc_sensor" actuator="arm_3_segment_1_out_of_plane_joint_torque_control"/>
    <framepos name="arm_3_segment_2_position_sensor" objtype="geom" objname="arm_3_segment_2_capsule"/>
    <jointpos name="arm_3_segment_2_in_plane_joint_jointpos_sensor" joint="arm_3_segment_2_in_plane_joint"/>
    <jointvel name="arm_3_segment_2_in_plane_joint_jointvel_sensor" joint="arm_3_segment_2_in_plane_joint"/>
    <jointactuatorfrc name="arm_3_segment_2_in_plane_joint_actuatorfrc_sensor" joint="arm_3_segment_2_in_plane_joint"/>
    <jointpos name="arm_3_segment_2_out_of_plane_joint_jointpos_sensor" joint="arm_3_segment_2_out_of_plane_joint"/>
    <jointvel name="arm_3_segment_2_out_of_plane_joint_jointvel_sensor" joint="arm_3_segment_2_out_of_plane_joint"/>
    <jointactuatorfrc name="arm_3_segment_2_out_of_plane_joint_actuatorfrc_sensor" joint="arm_3_segment_2_out_of_plane_joint"/>
    <actuatorfrc name="arm_3_segment_2_in_plane_joint_torque_control_actuatorfrc_sensor" actuator="arm_3_segment_2_in_plane_joint_torque_control"/>
    <actuatorfrc name="arm_3_segment_2_out_of_plane_joint_torque_control_actuatorfrc_sensor" actuator="arm_3_segment_2_out_of_plane_joint_torque_control"/>
    <framepos name="arm_3_segment_3_position_sensor" objtype="geom" objname="arm_3_segment_3_capsule"/>
    <jointpos name="arm_3_segment_3_in_plane_joint_jointpos_sensor" joint="arm_3_segment_3_in_plane_joint"/>
    <jointvel name="arm_3_segment_3_in_plane_joint_jointvel_sensor" joint="arm_3_segment_3_in_plane_joint"/>
    <jointactuatorfrc name="arm_3_segment_3_in_plane_joint_actuatorfrc_sensor" joint="arm_3_segment_3_in_plane_joint"/>
    <jointpos name="arm_3_segment_3_out_of_plane_joint_jointpos_sensor" joint="arm_3_segment_3_out_of_plane_joint"/>
    <jointvel name="arm_3_segment_3_out_of_plane_joint_jointvel_sensor" joint="arm_3_segment_3_out_of_plane_joint"/>
    <jointactuatorfrc name="arm_3_segment_3_out_of_plane_joint_actuatorfrc_sensor" joint="arm_3_segment_3_out_of_plane_joint"/>
    <actuatorfrc name="arm_3_segment_3_in_plane_joint_torque_control_actuatorfrc_sensor" actuator="arm_3_segment_3_in_plane_joint_torque_control"/>
    <actuatorfrc name="arm_3_segment_3_out_of_plane_joint_torque_control_actuatorfrc_sensor" actuator="arm_3_segment_3_out_of_plane_joint_torque_control"/>
    <framepos name="arm_3_segment_4_position_sensor" objtype="geom" objname="arm_3_segment_4_capsule"/>
    <jointpos name="arm_3_segment_4_in_plane_joint_jointpos_sensor" joint="arm_3_segment_4_in_plane_joint"/>
    <jointvel name="arm_3_segment_4_in_plane_joint_jointvel_sensor" joint="arm_3_segment_4_in_plane_joint"/>
    <jointactuatorfrc name="arm_3_segment_4_in_plane_joint_actuatorfrc_sensor" joint="arm_3_segment_4_in_plane_joint"/>
    <jointpos name="arm_3_segment_4_out_of_plane_joint_jointpos_sensor" joint="arm_3_segment_4_out_of_plane_joint"/>
    <jointvel name="arm_3_segment_4_out_of_plane_joint_jointvel_sensor" joint="arm_3_segment_4_out_of_plane_joint"/>
    <jointactuatorfrc name="arm_3_segment_4_out_of_plane_joint_actuatorfrc_sensor" joint="arm_3_segment_4_out_of_plane_joint"/>
    <actuatorfrc name="arm_3_segment_4_in_plane_joint_torque_control_actuatorfrc_sensor" actuator="arm_3_segment_4_in_plane_joint_torque_control"/>
    <actuatorfrc name="arm_3_segment_4_out_of_plane_joint_torque_control_actuatorfrc_sensor" actuator="arm_3_segment_4_out_of_plane_joint_torque_control"/>
    <framepos name="arm_4_segment_0_position_sensor" objtype="geom" objname="arm_4_segment_0_capsule"/>
    <jointpos name="arm_4_segment_0_in_plane_joint_jointpos_sensor" joint="arm_4_segment_0_in_plane_joint"/>
    <jointvel name="arm_4_segment_0_in_plane_joint_jointvel_sensor" joint="arm_4_segment_0_in_plane_joint"/>
    <jointactuatorfrc name="arm_4_segment_0_in_plane_joint_actuatorfrc_sensor" joint="arm_4_segment_0_in_plane_joint"/>
    <jointpos name="arm_4_segment_0_out_of_plane_joint_jointpos_sensor" joint="arm_4_segment_0_out_of_plane_joint"/>
    <jointvel name="arm_4_segment_0_out_of_plane_joint_jointvel_sensor" joint="arm_4_segment_0_out_of_plane_joint"/>
    <jointactuatorfrc name="arm_4_segment_0_out_of_plane_joint_actuatorfrc_sensor" joint="arm_4_segment_0_out_of_plane_joint"/>
    <actuatorfrc name="arm_4_segment_0_in_plane_joint_torque_control_actuatorfrc_sensor" actuator="arm_4_segment_0_in_plane_joint_torque_control"/>
    <actuatorfrc name="arm_4_segment_0_out_of_plane_joint_torque_control_actuatorfrc_sensor" actuator="arm_4_segment_0_out_of_plane_joint_torque_control"/>
    <framepos name="arm_4_segment_1_position_sensor" objtype="geom" objname="arm_4_segment_1_capsule"/>
    <jointpos name="arm_4_segment_1_in_plane_joint_jointpos_sensor" joint="arm_4_segment_1_in_plane_joint"/>
    <jointvel name="arm_4_segment_1_in_plane_joint_jointvel_sensor" joint="arm_4_segment_1_in_plane_joint"/>
    <jointactuatorfrc name="arm_4_segment_1_in_plane_joint_actuatorfrc_sensor" joint="arm_4_segment_1_in_plane_joint"/>
    <jointpos name="arm_4_segment_1_out_of_plane_joint_jointpos_sensor" joint="arm_4_segment_1_out_of_plane_joint"/>
    <jointvel name="arm_4_segment_1_out_of_plane_joint_jointvel_sensor" joint="arm_4_segment_1_out_of_plane_joint"/>
    <jointactuatorfrc name="arm_4_segment_1_out_of_plane_joint_actuatorfrc_sensor" joint="arm_4_segment_1_out_of_plane_joint"/>
    <actuatorfrc name="arm_4_segment_1_in_plane_joint_torque_control_actuatorfrc_sensor" actuator="arm_4_segment_1_in_plane_joint_torque_control"/>
    <actuatorfrc name="arm_4_segment_1_out_of_plane_joint_torque_control_actuatorfrc_sensor" actuator="arm_4_segment_1_out_of_plane_joint_torque_control"/>
    <framepos name="arm_4_segment_2_position_sensor" objtype="geom" objname="arm_4_segment_2_capsule"/>
    <jointpos name="arm_4_segment_2_in_plane_joint_jointpos_sensor" joint="arm_4_segment_2_in_plane_joint"/>
    <jointvel name="arm_4_segment_2_in_plane_joint_jointvel_sensor" joint="arm_4_segment_2_in_plane_joint"/>
    <jointactuatorfrc name="arm_4_segment_2_in_plane_joint_actuatorfrc_sensor" joint="arm_4_segment_2_in_plane_joint"/>
    <jointpos name="arm_4_segment_2_out_of_plane_joint_jointpos_sensor" joint="arm_4_segment_2_out_of_plane_joint"/>
    <jointvel name="arm_4_segment_2_out_of_plane_joint_jointvel_sensor" joint="arm_4_segment_2_out_of_plane_joint"/>
    <jointactuatorfrc name="arm_4_segment_2_out_of_plane_joint_actuatorfrc_sensor" joint="arm_4_segment_2_out_of_plane_joint"/>
    <actuatorfrc name="arm_4_segment_2_in_plane_joint_torque_control_actuatorfrc_sensor" actuator="arm_4_segment_2_in_plane_joint_torque_control"/>
    <actuatorfrc name="arm_4_segment_2_out_of_plane_joint_torque_control_actuatorfrc_sensor" actuator="arm_4_segment_2_out_of_plane_joint_torque_control"/>
    <framepos name="arm_4_segment_3_position_sensor" objtype="geom" objname="arm_4_segment_3_capsule"/>
    <jointpos name="arm_4_segment_3_in_plane_joint_jointpos_sensor" joint="arm_4_segment_3_in_plane_joint"/>
    <jointvel name="arm_4_segment_3_in_plane_joint_jointvel_sensor" joint="arm_4_segment_3_in_plane_joint"/>
    <jointactuatorfrc name="arm_4_segment_3_in_plane_joint_actuatorfrc_sensor" joint="arm_4_segment_3_in_plane_joint"/>
    <jointpos name="arm_4_segment_3_out_of_plane_joint_jointpos_sensor" joint="arm_4_segment_3_out_of_plane_joint"/>
    <jointvel name="arm_4_segment_3_out_of_plane_joint_jointvel_sensor" joint="arm_4_segment_3_out_of_plane_joint"/>
    <jointactuatorfrc name="arm_4_segment_3_out_of_plane_joint_actuatorfrc_sensor" joint="arm_4_segment_3_out_of_plane_joint"/>
    <actuatorfrc name="arm_4_segment_3_in_plane_joint_torque_control_actuatorfrc_sensor" actuator="arm_4_segment_3_in_plane_joint_torque_control"/>
    <actuatorfrc name="arm_4_segment_3_out_of_plane_joint_torque_control_actuatorfrc_sensor" actuator="arm_4_segment_3_out_of_plane_joint_torque_control"/>
    <framepos name="arm_4_segment_4_position_sensor" objtype="geom" objname="arm_4_segment_4_capsule"/>
    <jointpos name="arm_4_segment_4_in_plane_joint_jointpos_sensor" joint="arm_4_segment_4_in_plane_joint"/>
    <jointvel name="arm_4_segment_4_in_plane_joint_jointvel_sensor" joint="arm_4_segment_4_in_plane_joint"/>
    <jointactuatorfrc name="arm_4_segment_4_in_plane_joint_actuatorfrc_sensor" joint="arm_4_segment_4_in_plane_joint"/>
    <jointpos name="arm_4_segment_4_out_of_plane_joint_jointpos_sensor" joint="arm_4_segment_4_out_of_plane_joint"/>
    <jointvel name="arm_4_segment_4_out_of_plane_joint_jointvel_sensor" joint="arm_4_segment_4_out_of_plane_joint"/>
    <jointactuatorfrc name="arm_4_segment_4_out_of_plane_joint_actuatorfrc_sensor" joint="arm_4_segment_4_out_of_plane_joint"/>
    <actuatorfrc name="arm_4_segment_4_in_plane_joint_torque_control_actuatorfrc_sensor" actuator="arm_4_segment_4_in_plane_joint_torque_control"/>
    <actuatorfrc name="arm_4_segment_4_out_of_plane_joint_torque_control_actuatorfrc_sensor" actuator="arm_4_segment_4_out_of_plane_joint_torque_control"/>
  </sensor>
</mujoco>
